<?xml version="1.0" ?>
<sdf version="1.6">
  <world name="default">
    <include>
      <uri>model://ground_plane</uri>
    </include>

    <include>
      <uri>model://sun</uri>
    </include>

    <physics type="ode">
      <real_time_update_rate>1000.0</real_time_update_rate>
    </physics>

    <!-- Adding Conveyor plugin -->

<!-- SDF conveyor belt: -->

   <model name="conveyor_belt">
  
     <model name="conveyor_belt_fixed">
       <static>true</static>
       <pose>0.5 -2 0.05 0 0 -1.57079</pose>
       <link name="link">
         <pose>0 0 0 0 0 0</pose>
         <!--Uncomment for debugging -->
         <visual name="belt_fixed_visual">
           <geometry>
             <box>
               <size>14.62206 0.75461 0.07862</size>
             </box>
           </geometry>
         </visual>
       </link>

     </model>
  
     <model name="conveyor_belt_moving">
       <allow_auto_disable>0</allow_auto_disable>
       <static>false</static>
       <pose>0.5 -2 0.05 0 0 -1.57079</pose>
       <link name="belt">
         <pose>0 0 0 0 0 0</pose>
         <inertial>
           <inertia>
             <ixx>3.8185</ixx>
             <ixy>0</ixy>
             <ixz>0</ixz>
             <iyy>1781.5</iyy>
             <iyz>0</iyz>
             <izz>1784.72</izz>
           </inertia>
           <mass>100</mass>
         </inertial>

         <!--Uncomment for debugging -->

         <visual name="belt_visual">
           <geometry>
             <box>
               <size>14.62206 0.65461 0.08862</size>
             </box>
           </geometry>
            <material>
              <ambient>0.1 0.1 0.1 1</ambient>
            </material>
         </visual>

         <collision name="belt_collision">
           <geometry>
             <box>
               <size>14.62206 0.65461 0.08862</size>
             </box>
           </geometry>
           <surface>
             <friction>
               <ode>
                 <mu>1000.0</mu>
                 <mu2>1000.0</mu2>
               </ode>
               <torsional>
                 <coefficient>1000.0</coefficient>
                 <patch_radius>0.2</patch_radius>
               </torsional>
             </friction>
           </surface>
         </collision>
       </link>
     </model>
  
     <joint name="belt_joint" type="prismatic">
       <parent>conveyor_belt_fixed::link</parent>
       <child>conveyor_belt_moving::belt</child>
       <axis>
         <xyz>1 0 0</xyz>
         <limit>
           <lower>0</lower>
           <upper>1.0</upper>
         </limit>
       </axis>
     </joint>
  
     <plugin name="conveyor_belt_plugin" filename="libROSConveyorBeltPlugin.so">
       <robot_namespace>/robot_ns</robot_namespace>
       <link>conveyor_belt::conveyor_belt_moving::belt</link>
       <power>50.0</power>
       <update_rate>10</update_rate>
       <max_velocity>0.2</max_velocity>
     </plugin>
    </model>



<!-- object model -->

    <model name="object">
        <pose>0.48 1.5 1.0 0 0 0</pose>
        <static>false</static>
        <link name="obj_link">
          <inertial>
            <mass>1.0</mass>
            <inertia> <!-- inertias are tricky to compute -->
              <!-- http://gazebosim.org/tutorials?tut=inertia&cat=build_robot -->
              <ixx>0.00166</ixx>       <!-- for a box: ixx = 0.083 * mass * (y*y + z*z) -->
              <ixy>0.0</ixy>         <!-- for a box: ixy = 0 -->
              <ixz>0.0</ixz>         <!-- for a box: ixz = 0 -->
              <iyy>0.00166</iyy>       <!-- for a box: iyy = 0.083 * mass * (x*x + z*z) -->
              <iyz>0.0</iyz>         <!-- for a box: iyz = 0 -->
              <izz>0.00166</izz>       <!-- for a box: izz = 0.083 * mass * (x*x + y*y) -->
            </inertia>
          </inertial>
          <collision name="collision">
            <geometry>
              <box>
                <size>0.1 0.1 0.1</size>
              </box>
            </geometry>
            <surface>
             <friction>
               <ode>
                 <mu>2.0</mu>
                 <mu2>2.0</mu2>
               </ode>
               <torsional>
                 <coefficient>1000.0</coefficient>
                 <patch_radius>0.2</patch_radius>
               </torsional>
             </friction>
           </surface>
          </collision>
          <visual name="visual">
            <geometry>
              <box>
                <size>0.1 0.1 0.1</size>
              </box>
            </geometry>
            <material>
              <ambient>0 1 0 1</ambient>
            </material>
          </visual>
        </link>
      </model>

      <!-- Add camera -->
      <model name="camera">
        <static>true</static>
        <link name="camera_link">
          <pose>0.5 0.0 1.5 0 1.570 0</pose>
          <inertial>
            <mass>0.1</mass>
            <inertia>
              <ixx>0.000166667</ixx>
              <iyy>0.000166667</iyy>
              <izz>0.000166667</izz>
            </inertia>
          </inertial>
          <collision name="collision">
            <geometry>
              <box>
                <size>0.1 0.1 0.1</size>
              </box>
            </geometry>
          </collision>
          <visual name="visual">
            <geometry>
              <box>
                <size>0.1 0.1 0.1</size>
              </box>
            </geometry>
          </visual>
          <sensor type="camera" name="camera1">
            <update_rate>30.0</update_rate>
            <visualize>true</visualize>
            <always_on>1</always_on>
            <camera name="head">
              <horizontal_fov>1.3962634</horizontal_fov>
              <image>
                <width>320</width>
                <height>240</height>
                <format>R8G8B8</format>
              </image>
              <clip>
                <near>0.1</near>
                <far>100</far>
              </clip>
              <noise>
                <type>gaussian</type>
                <!-- Noise is sampled independently per pixel on each frame.
                     That pixel's noise value is added to each of its color
                     channels, which at that point lie in the range [0,1]. -->
                <mean>0.0</mean>
                <stddev>0.007</stddev>
              </noise>
            </camera>
            <plugin name="camera_controller" filename="libgazebo_ros_camera.so">
              <alwaysOn>true</alwaysOn>
              <updateRate>30.0</updateRate>
              <cameraName>camera1</cameraName>
              <imageTopicName>image_raw</imageTopicName>
              <cameraInfoTopicName>camera_info</cameraInfoTopicName>
              <frameName>camera_link</frameName>
              <hackBaseline>0.07</hackBaseline>
              <distortionK1>0.0</distortionK1>
              <distortionK2>0.0</distortionK2>
              <distortionK3>0.0</distortionK3>
              <distortionT1>0.0</distortionT1>
              <distortionT2>0.0</distortionT2>
            </plugin>

          </sensor>
        </link>
      </model>

    <gravity>
      0.0 0.0 -9.6
    </gravity>

    <gui fullscreen='0'>
    </gui>

  </world>
</sdf>
